Workbook

Sheet Ordenes
A1: OrderKey | B1: FechaIngreso | C1: HoraIngreso | D1: Tipo | E1: FuenteTipo | F1: StatusDesc | G1: UnidadesPedidas | H1: Unidades BBDD | I1: Diff | J1: Unid_Accesories | K1: Unid_Apparel | L1: Unid_Footwear | M1: UnidadesConfirmadas | N1: FechaConfirmacion | O1: Quiebre
A2: 0000764635 | B2: 46296 | C2: 00:10:37 | D2: Single | E2: Inferido (unidades BWD) | F2: 9 · Despachada | G2: 1 | H2: =+VLOOKUP(A2,BBDD!B:E,4,0) -> 1 | I2: =+H2-G2 -> 0 | J2: 0 | K2: 0 | L2: 1 | M2: 1 | N2: 46296 | O2: 0
A3: 0000764636 | B3: 46296 | C3: 00:10:37 | D3: Single | E3: Inferido (unidades BWD) | F3: 9 · Despachada | G3: 1 | H3: =+VLOOKUP(A3,BBDD!B:E,4,0) -> 1 | I3: =+H3-G3 -> 0 | J3: 0 | K3: 0 | L3: 1 | M3: 1 | N3: 46296 | O3: 0
A4: 0000764637 | B4: 46296 | C4: 00:10:38 | D4: Single | E4: BWD | F4: 9 · Despachada | G4: 1 | H4: =+VLOOKUP(A4,BBDD!B:E,4,0) -> 1 | I4: =+H4-G4 -> 0 | J4: 0 | K4: 0 | L4: 1 | M4: 1 | N4: 46296 | O4: 0
A5: 0000764638 | B5: 46296 | C5: 00:10:38 | D5: Single | E5: BWD | F5: 9 · Despachada | G5: 1 | H5: =+VLOOKUP(A5,BBDD!B:E,4,0) -> 1 | I5: =+H5-G5 -> 0 | J5: 0 | K5: 0 | L5: 1 | M5: 1 | N5: 46296 | O5: 0
A6: 0000764639 | B6: 46296 | C6: 00:10:38 | D6: Single | E6: Inferido (unidades BWD) | F6: 9 · Despachada | G6: 1 | H6: =+VLOOKUP(A6,BBDD!B:E,4,0) -> 1 | I6: =+H6-G6 -> 0 | J6: 0 | K6: 0 | L6: 1 | M6: 1 | N6: 46296 | O6: 0
A7: 0000764640 | B7: 46296 | C7: 00:10:38 | D7: Single | E7: Inferido (unidades BWD) | F7: 9 · Despachada | G7: 1 | H7: =+VLOOKUP(A7,BBDD!B:E,4,0) -> 1 | I7: =+H7-G7 -> 0 | J7: 0 | K7: 0 | L7: 1 | M7: 1 | N7: 46296 | O7: 0
A8: 0000764641 | B8: 46296 | C8: 00:10:38 | D8: Single | E8: BWD | F8: 9 · Despachada | G8: 1 | H8: =+VLOOKUP(A8,BBDD!B:E,4,0) -> 1 | I8: =+H8-G8 -> 0 | J8: 0 | K8: 0 | L8: 1 | M8: 1 | N8: 46296 | O8: 0
A9: 0000764642 | B9: 46296 | C9: 00:10:38 | D9: Single | E9: BWD | F9: 9 · Despachada | G9: 1 | H9: =+VLOOKUP(A9,BBDD!B:E,4,0) -> 1 | I9: =+H9-G9 -> 0 | J9: 0 | K9: 0 | L9: 1 | M9: 1 | N9: 46296 | O9: 0
A10: 0000764643 | B10: 46296 | C10: 00:10:38 | D10: Multi | E10: BWD | F10: 9 · Despachada | G10: 2 | H10: =+VLOOKUP(A10,BBDD!B:E,4,0) -> 2 | I10: =+H10-G10 -> 0 | J10: 0 | K10: 0 | L10: 2 | M10: 2 | N10: 46296 | O10: 0
A11: 0000764644 | B11: 46296 | C11: 00:15:37 | D11: Multi | E11: BWD | F11: 9 · Despachada | G11: 2 | H11: =+VLOOKUP(A11,BBDD!B:E,4,0) -> 2 | I11: =+H11-G11 -> 0 | J11: 0 | K11: 0 | L11: 2 | M11: 2 | N11: 46296 | O11: 0
A12: 0000764645 | B12: 46296 | C12: 00:15:37 | D12: Single | E12: Inferido (unidades BWD) | F12: 9 · Despachada | G12: 1 | H12: =+VLOOKUP(A12,BBDD!B:E,4,0) -> 1 | I12: =+H12-G12 -> 0 | J12: 0 | K12: 0 | L12: 1 | M12: 1 | N12: 46296 | O12: 0
A13: 0000764646 | B13: 46296 | C13: 00:15:37 | D13: Single | E13: Inferido (unidades BWD) | F13: 9 · Despachada | G13: 1 | H13: =+VLOOKUP(A13,BBDD!B:E,4,0) -> 1 | I13: =+H13-G13 -> 0 | J13: 0 | K13: 0 | L13: 1 | M13: 1 | N13: 46296 | O13: 0
... A635: 0000765547 | B635: 46297 | C635: 10:15:38 | D635: Single | E635: BWD | F635: 5 · Confirmada | G635: 1 | H635: =+VLOOKUP(A635,BBDD!B:E,4,0) -> 1 | I635: =+H635-G635 -> 0 | J635: 0 | K635: 0 | L635: 1 | M635: 1 | N635: 46297 | O635: 0
A636: 0000765548 | B636: 46297 | C636: 10:25:37 | D636: Multi | E636: BWD | F636: 2 · Asignada | G636: 2 | H636: =+VLOOKUP(A636,BBDD!B:E,4,0) -> 2 | I636: =+H636-G636 -> 0 | J636: 0 | K636: 0 | L636: 2 | M636: 0 | O636: 0
A637: 0000765549 | B637: 46297 | C637: 10:25:37 | D637: Single | E637: BWD | F637: 5 · Confirmada | G637: 1 | H637: =+VLOOKUP(A637,BBDD!B:E,4,0) -> 1 | I637: =+H637-G637 -> 0 | J637: 0 | K637: 0 | L637: 1 | M637: 1 | N637: 46297 | O637: 0
A638: 0000765550 | B638: 46297 | C638: 10:25:37 | D638: Single | E638: BWD | F638: 5 · Confirmada | G638: 1 | H638: =+VLOOKUP(A638,BBDD!B:E,4,0) -> 1 | I638: =+H638-G638 -> 0 | J638: 0 | K638: 0 | L638: 1 | M638: 1 | N638: 46297 | O638: 0
A639: 0000765551 | B639: 46297 | C639: 10:25:37 | D639: Multi | E639: BWD | F639: 5 · Confirmada | G639: 2 | H639: =+VLOOKUP(A639,BBDD!B:E,4,0) -> 2 | I639: =+H639-G639 -> 0 | J639: 0 | K639: 1 | L639: 1 | M639: 2 | N639: 46297 | O639: 0
A640: 0000765552 | B640: 46297 | C640: 10:25:38 | D640: Single | E640: BWD | F640: 5 · Confirmada | G640: 1 | H640: =+VLOOKUP(A640,BBDD!B:E,4,0) -> 1 | I640: =+H640-G640 -> 0 | J640: 0 | K640: 0 | L640: 1 | M640: 1 | N640: 46297 | O640: 0
A641: 0000765553 | B641: 46297 | C641: 10:25:38 | D641: Single | E641: BWD | F641: 5 · Confirmada | G641: 1 | H641: =+VLOOKUP(A641,BBDD!B:E,4,0) -> 1 | I641: =+H641-G641 -> 0 | J641: 1 | K641: 0 | L641: 0 | M641: 1 | N641: 46297 | O641: 0
A642: 0000765554 | B642: 46297 | C642: 10:25:38 | D642: Multi | E642: BWD | F642: 5 · Confirmada | G642: 3 | H642: =+VLOOKUP(A642,BBDD!B:E,4,0) -> 3 | I642: =+H642-G642 -> 0 | J642: 0 | K642: 2 | L642: 1 | M642: 3 | N642: 46297 | O642: 0
A643: 0000765555 | B643: 46297 | C643: 10:55:37 | D643: Single | E643: BWD | F643: 5 · Confirmada | G643: 1 | H643: =+VLOOKUP(A643,BBDD!B:E,4,0) -> 1 | I643: =+H643-G643 -> 0 | J643: 0 | K643: 0 | L643: 1 | M643: 1 | N643: 46297 | O643: 0
A644: 0000765556 | B644: 46297 | C644: 10:55:37 | D644: Multi | E644: BWD | F644: 5 · Confirmada | G644: 3 | H644: =+VLOOKUP(A644,BBDD!B:E,4,0) -> 3 | I644: =+H644-G644 -> 0 | J644: 0 | K644: 0 | L644: 3 | M644: 3 | N644: 46297 | O644: 0
A645: 0000765557 | B645: 46297 | C645: 10:55:37 | D645: Single | E645: BWD | F645: 5 · Confirmada | G645: 1 | H645: =+VLOOKUP(A645,BBDD!B:E,4,0) -> 1 | I645: =+H645-G645 -> 0 | J645: 0 | K645: 1 | L645: 0 | M645: 1 | N645: 46297 | O645: 0
A646: 0000765558 | B646: 46297 | C646: 10:55:38 | D646: Single | E646: BWD | F646: 5 · Confirmada | G646: 1 | H646: =+VLOOKUP(A646,BBDD!B:E,4,0) -> 1 | I646: =+H646-G646 -> 0 | J646: 0 | K646: 0 | L646: 1 | M646: 1 | N646: 46297 | O646: 0
A647: 0000765559 | B647: 46297 | C647: 10:55:38 | D647: Single | E647: BWD | F647: 5 · Confirmada | G647: 1 | H647: =+VLOOKUP(A647,BBDD!B:E,4,0) -> 1 | I647: =+H647-G647 -> 0 | J647: 0 | K647: 0 | L647: 1 | M647: 1 | N647: 46297 | O647: 0
A648: 0000765560 | B648: 46297 | C648: 10:55:38 | D648: Single | E648: BWD | F648: 5 · Confirmada | G648: 1 | H648: =+VLOOKUP(A648,BBDD!B:E,4,0) -> 1 | I648: =+H648-G648 -> 0 | J648: 0 | K648: 0 | L648: 1 | M648: 1 | N648: 46297 | O648: 0
... A654: 0000765566 | B654: 46297 | C654: 11:26:00 | D654: Multi | E654: BWD | F654: 5 · Confirmada | G654: 2 | H654: =+VLOOKUP(A654,BBDD!B:E,4,0) -> 2 | I654: =+H654-G654 -> 0 | J654: 0 | K654: 0 | L654: 2 | M654: 2 | N654: 46297 | O654: 0
A655: 0000765567 | B655: 46297 | C655: 11:26:00 | D655: Multi | E655: BWD | F655: 2 · Asignada | G655: 2 | H655: =+VLOOKUP(A655,BBDD!B:E,4,0) -> 2 | I655: =+H655-G655 -> 0 | J655: 0 | K655: 0 | L655: 2 | M655: 0 | O655: 0
A656: 0000765568 | B656: 46297 | C656: 11:26:00 | D656: Single | E656: BWD | F656: 5 · Confirmada | G656: 1 | H656: =+VLOOKUP(A656,BBDD!B:E,4,0) -> 1 | I656: =+H656-G656 -> 0 | J656: 0 | K656: 0 | L656: 1 | M656: 1 | N656: 46297 | O656: 0
A657: 0000765569 | B657: 46297 | C657: 11:26:01 | D657: Single | E657: BWD | F657: 5 · Confirmada | G657: 1 | H657: =+VLOOKUP(A657,BBDD!B:E,4,0) -> 1 | I657: =+H657-G657 -> 0 | J657: 0 | K657: 0 | L657: 1 | M657: 1 | N657: 46297 | O657: 0
A658: 0000765570 | B658: 46297 | C658: 11:26:01 | D658: Single | E658: BWD | F658: 5 · Confirmada | G658: 1 | H658: =+VLOOKUP(A658,BBDD!B:E,4,0) -> 1 | I658: =+H658-G658 -> 0 | J658: 0 | K658: 1 | L658: 0 | M658: 1 | N658: 46297 | O658: 0
A659: 0000765571 | B659: 46297 | C659: 11:26:01 | D659: Single | E659: BWD | F659: 2 · Asignada | G659: 1 | H659: =+VLOOKUP(A659,BBDD!B:E,4,0) -> 1 | I659: =+H659-G659 -> 0 | J659: 0 | K659: 0 | L659: 1 | M659: 0 | O659: 0
A660: 0000765572 | B660: 46297 | C660: 11:26:01 | D660: Single | E660: BWD | F660: 5 · Confirmada | G660: 1 | H660: =+VLOOKUP(A660,BBDD!B:E,4,0) -> 1 | I660: =+H660-G660 -> 0 | J660: 0 | K660: 0 | L660: 1 | M660: 1 | N660: 46297 | O660: 0
A661: 0000765573 | B661: 46297 | C661: 11:26:01 | D661: Single | E661: BWD | F661: 5 · Confirmada | G661: 1 | H661: =+VLOOKUP(A661,BBDD!B:E,4,0) -> 1 | I661: =+H661-G661 -> 0 | J661: 0 | K661: 0 | L661: 1 | M661: 1 | N661: 46297 | O661: 0
A662: 0000765574 | B662: 46297 | C662: 11:26:02 | D662: Single | E662: BWD | F662: 5 · Confirmada | G662: 1 | H662: =+VLOOKUP(A662,BBDD!B:E,4,0) -> 1 | I662: =+H662-G662 -> 0 | J662: 0 | K662: 0 | L662: 1 | M662: 1 | N662: 46297 | O662: 0
A663: 0000765575 | B663: 46297 | C663: 11:26:02 | D663: Single | E663: BWD | F663: 5 · Confirmada | G663: 1 | H663: =+VLOOKUP(A663,BBDD!B:E,4,0) -> 1 | I663: =+H663-G663 -> 0 | J663: 0 | K663: 0 | L663: 1 | M663: 1 | N663: 46297 | O663: 0
A664: 0000765576 | B664: 46297 | C664: 11:26:02 | D664: Single | E664: BWD | F664: 5 · Confirmada | G664: 1 | H664: =+VLOOKUP(A664,BBDD!B:E,4,0) -> 1 | I664: =+H664-G664 -> 0 | J664: 0 | K664: 1 | L664: 0 | M664: 1 | N664: 46297 | O664: 0
A665: 0000765577 | B665: 46297 | C665: 11:45:37 | D665: Single | E665: BWD | F665: 5 · Confirmada | G665: 1 | H665: =+VLOOKUP(A665,BBDD!B:E,4,0) -> 1 | I665: =+H665-G665 -> 0 | J665: 0 | K665: 0 | L665: 1 | M665: 1 | N665: 46297 | O665: 0
A666: 0000765578 | B666: 46297 | C666: 11:55:37 | D666: Single | E666: BWD | F666: 5 · Confirmada | G666: 1 | H666: =+VLOOKUP(A666,BBDD!B:E,4,0) -> 1 | I666: =+H666-G666 -> 0 | J666: 0 | K666: 0 | L666: 1 | M666: 1 | N666: 46297 | O666: 0
...

Sheet BBDD
A1: seller_order | B1: Orderkey | C1: Cliente | D1: status | E1: qty_original | F1: qty_allocated | G1: qty_picked | H1: qty_shipped | I1: AddDate | J1: DeliveryDate | K1: Canal | L1: Categoria
A2: 0820444535 | B2: 0000764705 | C2: Doris Agustina Tello Adones | D2: 9 | E2: 1 | F2: 0 | G2: 0 | H2: 1 | I2: 2026-10-01 | J2: 2026-10-01 | K2: ECM | L2: Footwear
A3: 0820444536 | B3: 0000764706 | C3: Miguel Calfin | D3: 9 | E3: 1 | F3: 0 | G3: 0 | H3: 1 | I3: 2026-10-01 | J3: 2026-10-01 | K3: ECM | L3: Footwear
A4: 0820444537 | B4: 0000764707 | C4: Carolina Espinoza | D4: 9 | E4: 1 | F4: 0 | G4: 0 | H4: 1 | I4: 2026-10-01 | J4: 2026-10-01 | K4: ECM | L4: Footwear
A5: 0820444538 | B5: 0000764708 | C5: Miguel Angel Alvarez Arce | D5: 9 | E5: 1 | F5: 0 | G5: 0 | H5: 1 | I5: 2026-10-01 | J5: 2026-10-01 | K5: ECM | L5: Apparel
A6: 0820444544 | B6: 0000764714 | C6: Guillermo Villegas Veliz | D6: 9 | E6: 2 | F6: 0 | G6: 0 | H6: 2 | I6: 2026-10-01 | J6: 2026-10-01 | K6: ECM | L6: Accessories
A7: 0820444545 | B7: 0000764715 | C7: jose gonzalez | D7: 9 | E7: 1 | F7: 0 | G7: 0 | H7: 1 | I7: 2026-10-01 | J7: 2026-10-01 | K7: ECM | L7: Footwear
A8: 0820444546 | B8: 0000764716 | C8: Mayur Patel | D8: 9 | E8: 1 | F8: 0 | G8: 0 | H8: 1 | I8: 2026-10-01 | J8: 2026-10-01 | K8: ECM | L8: Footwear
A9: 0820444547 | B9: 0000764717 | C9: Elias Diaz Palominos | D9: 9 | E9: 1 | F9: 0 | G9: 0 | H9: 1 | I9: 2026-10-01 | J9: 2026-10-01 | K9: ECM | L9: Apparel
A10: 0820444553 | B10: 0000764723 | C10: Julian Eduardo Chavez Perez | D10: 9 | E10: 1 | F10: 0 | G10: 0 | H10: 1 | I10: 2026-10-01 | J10: 2026-10-01 | K10: ECM | L10: Apparel
A11: 0820444554 | B11: 0000764724 | C11: Jacqueline Donoso | D11: 9 | E11: 1 | F11: 0 | G11: 0 | H11: 1 | I11: 2026-10-01 | J11: 2026-10-01 | K11: ECM | L11: Footwear
A12: 0820444555 | B12: 0000764725 | C12: Abel Reinoso Parra | D12: 9 | E12: 3 | F12: 0 | G12: 0 | H12: 3 | I12: 2026-10-01 | J12: 2026-10-01 | K12: ECM | L12: Accessories
A13: 0820444556 | B13: 0000764726 | C13: Nicolás Jara | D13: 9 | E13: 2 | F13: 0 | G13: 0 | H13: 2 | I13: 2026-10-01 | J13: 2026-10-01 | K13: ECM | L13: Footwear
... A2152: 0820446739 | B2152: 0000765981 | C2152: Katty Carvajal | D2152: 2 | E2152: 1 | F2152: 1 | G2152: 0 | H2152: 0 | I2152: 2026-10-02 | J2152: 2026-10-02 | K2152: ECM | L2152: Footwear
A2153: 0820446741 | B2153: 0000765982 | C2153: Fernando Pinto | D2153: CANC | E2153: 1 | F2153: 0 | G2153: 0 | H2153: 0 | I2153: 2026-10-02 | J2153: 2026-10-02 | K2153: ECM | L2153: Footwear
A2154: 0820446742 | B2154: 0000765983 | C2154: Roberto Orellana | D2154: 5 | E2154: 2 | F2154: 0 | G2154: 2 | H2154: 0 | I2154: 2026-10-02 | J2154: 2026-10-02 | K2154: ECM | L2154: Footwear
A2155: 0820446743 | B2155: 0000765984 | C2155: silvia gonzalez | D2155: 5 | E2155: 2 | F2155: 0 | G2155: 2 | H2155: 0 | I2155: 2026-10-02 | J2155: 2026-10-02 | K2155: ECM | L2155: Footwear
A2156: 0820446745 | B2156: 0000765985 | C2156: Marcela Calderón | D2156: 3 | E2156: 1 | F2156: 1 | G2156: 0 | H2156: 0 | I2156: 2026-10-02 | J2156: 2026-10-02 | K2156: ECM | L2156: Footwear
A2157: 0820446744 | B2157: 0000765986 | C2157: Isabel Vejar | D2157: 5 | E2157: 1 | F2157: 0 | G2157: 1 | H2157: 0 | I2157: 2026-10-02 | J2157: 2026-10-02 | K2157: ECM | L2157: Footwear
A2158: 0820446746 | B2158: 0000765987 | C2158: Melissa rivera Castilla | D2158: 5 | E2158: 2 | F2158: 0 | G2158: 2 | H2158: 0 | I2158: 2026-10-02 | J2158: 2026-10-02 | K2158: ECM | L2158: Footwear
A2159: 0820446748 | B2159: 0000765988 | C2159: Teresa Onate | D2159: 5 | E2159: 1 | F2159: 0 | G2159: 1 | H2159: 0 | I2159: 2026-10-02 | J2159: 2026-10-02 | K2159: ECM | L2159: Footwear
A2160: 0820446747 | B2160: 0000765989 | C2160: karla constanza jaque parra | D2160: 5 | E2160: 1 | F2160: 0 | G2160: 1 | H2160: 0 | I2160: 2026-10-02 | J2160: 2026-10-02 | K2160: ECM | L2160: Apparel
A2161: 0820446749 | B2161: 0000765990 | C2161: Jisleiner Anais Jiménez Maluenda | D2161: 5 | E2161: 1 | F2161: 0 | G2161: 1 | H2161: 0 | I2161: 2026-10-02 | J2161: 2026-10-02 | K2161: ECM | L2161: Footwear
A2162: 0820446750 | B2162: 0000765991 | C2162: brainer perez | D2162: 3 | E2162: 1 | F2162: 1 | G2162: 0 | H2162: 0 | I2162: 2026-10-02 | J2162: 2026-10-02 | K2162: ECM | L2162: Apparel
A2163: 0820446751 | B2163: 0000765992 | C2163: Jose Miguel Cardenas Solis | D2163: 3 | E2163: 1 | F2163: 1 | G2163: 0 | H2163: 0 | I2163: 2026-10-02 | J2163: 2026-10-02 | K2163: ECM | L2163: Footwear
A2164: 0820446752 | B2164: 0000765993 | C2164: marcela polanco | D2164: 5 | E2164: 1 | F2164: 0 | G2164: 1 | H2164: 0 | I2164: 2026-10-02 | J2164: 2026-10-02 | K2164: ECM | L2164: Footwear
A2165: 0820446753 | B2165: 0000765994 | C2165: Nicolas Godoy | D2165: 5 | E2165: 3 | F2165: 0 | G2165: 3 | H2165: 0 | I2165: 2026-10-02 | J2165: 2026-10-02 | K2165: ECM | L2165: Footwear
... A3583: 0820449215 | B3583: 0000768163 | C3583: Ernestina Gallardo | D3583: 3 | E3583: 1 | F3583: 1 | G3583: 0 | H3583: 0 | I3583: 2026-10-05 | J3583: 2026-10-05 | K3583: ECM | L3583: Footwear
